Workbook
Name Cadastro: Tabela1[]

Sheet CADASTRO DE FUNCIONÁRIOS
C1: Cadastro de funcionários
A4: Funcionário | B4: Cargo | C4: Departamento | D4: Salário bruto | E4: Regime de contratação | F4: Valor hora extra
A5: Katarina Damasceno | B5: Diretora | C5: Operações | D5: 20000 | E5: PJ | F5: =IF(Tabela1[[#This Row],[Regime de contratação]]="CLT",Tabela1[[#This Row],[Salário bruto]]*1.5/220,0) -> 0
A6: Jorge Henrique Martins | B6: Coordenador | C6: Finanças | D6: 8000 | E6: CLT | F6: =IF(Tabela1[[#This Row],[Regime de contratação]]="CLT",Tabela1[[#This Row],[Salário bruto]]*1.5/220,0) -> 54.545455
A7: Mariana Dias | B7: Especialista | C7: Logistica | D7: 6500 | E7: CLT | F7: =IF(Tabela1[[#This Row],[Regime de contratação]]="CLT",Tabela1[[#This Row],[Salário bruto]]*1.5/220,0) -> 44.318182
A8: Leonargo Rangel | B8: Analista sênior | C8: Recursos Humanos | D8: 4000 | E8: CLT | F8: =IF(Tabela1[[#This Row],[Regime de contratação]]="CLT",Tabela1[[#This Row],[Salário bruto]]*1.5/220,0) -> 27.272727
A9: Luana Silva | B9: Analista | C9: Marketing | D9: 3000 | E9: CLT | F9: =IF(Tabela1[[#This Row],[Regime de contratação]]="CLT",Tabela1[[#This Row],[Salário bruto]]*1.5/220,0) -> 20.454545
A10: Thiago Gonçalves | B10: Estagiário | C10: Operações | D10: 2000 | E10: Estágio | F10: =IF(Tabela1[[#This Row],[Regime de contratação]]="CLT",Tabela1[[#This Row],[Salário bruto]]*1.5/220,0) -> 0
A11: Lucas da Rocha | B11: Jovem aprendiz | C11: Finanças | D11: 1000 | E11: Jovem aprendiz | F11: =IF(Tabela1[[#This Row],[Regime de contratação]]="CLT",Tabela1[[#This Row],[Salário bruto]]*1.5/220,0) -> 0
A12: Maria Julia Ribeiro | B12: Secretária | C12: Recursos Humanos | D12: 2400 | E12: CLT | F12: =IF(Tabela1[[#This Row],[Regime de contratação]]="CLT",Tabela1[[#This Row],[Salário bruto]]*1.5/220,0) -> 16.363636
A13: Liliam da Silva Prado | B13: Auxiliar administrativo | C13: Finanças | D13: 1800 | E13: CLT | F13: =IF(Tabela1[[#This Row],[Regime de contratação]]="CLT",Tabela1[[#This Row],[Salário bruto]]*1.5/220,0) -> 12.272727

Sheet CÁLCULO
F1: Folha de pagamentos
A4: Funcionários | B4: Competência | C4: Data do pagamento | D4: Quantidade HE | E4: Salário bruto | F4: Desconto transporte | G4: Desconto IR | H4: Desconto INSS | I4: Outros descontos | J4: Valor da hora extra | K4: Salário líquido
A5: Katarina Damasceno | B5: 45292 | C5: 45323 | D5: 3 | E5: =VLOOKUP(Tabela2[[#This Row],[Funcionários]],'CADASTRO DE FUNCIONÁRIOS'!A:F,4,0) -> 20000 | F5: 1000 | G5: 2400 | H5: 1800 | I5: 150 | J5: =Tabela2[[#This Row],[Quantidade HE]]*VLOOKUP(Tabela2[[#This Row],[Funcionários]],'CADASTRO DE FUNCIONÁRIOS'!A:F,6,0) -> 0 | K5: =Tabela2[[#This Row],[Salário bruto]]-(SUM(Tabela2[[#This Row],[Desconto transporte]:[Outros descontos]]))+Tabela2[[#This Row],[Valor da hora extra]] -> 14650
A6: Jorge Henrique Martins | B6: 45292 | C6: 45323 | D6: 5 | E6: =VLOOKUP(Tabela2[[#This Row],[Funcionários]],'CADASTRO DE FUNCIONÁRIOS'!A:F,4,0) -> 8000 | F6: 560 | G6: 960 | H6: 640 | I6: 137 | J6: =Tabela2[[#This Row],[Quantidade HE]]*VLOOKUP(Tabela2[[#This Row],[Funcionários]],'CADASTRO DE FUNCIONÁRIOS'!A:F,6,0) -> 272.72727 | K6: =Tabela2[[#This Row],[Salário bruto]]-(SUM(Tabela2[[#This Row],[Desconto transporte]:[Outros descontos]]))+Tabela2[[#This Row],[Valor da hora extra]] -> 5975.7273
A7: Mariana Dias | B7: 45292 | C7: 45323 | D7: 2 | E7: =VLOOKUP(Tabela2[[#This Row],[Funcionários]],'CADASTRO DE FUNCIONÁRIOS'!A:F,4,0) -> 6500 | F7: 390 | G7: 715 | H7: 650 | I7: 119 | J7: =Tabela2[[#This Row],[Quantidade HE]]*VLOOKUP(Tabela2[[#This Row],[Funcionários]],'CADASTRO DE FUNCIONÁRIOS'!A:F,6,0) -> 88.636364 | K7: =Tabela2[[#This Row],[Salário bruto]]-(SUM(Tabela2[[#This Row],[Desconto transporte]:[Outros descontos]]))+Tabela2[[#This Row],[Valor da hora extra]] -> 4714.6364
A8: Leonargo Rangel | B8: 45292 | C8: 45323 | D8: 3 | E8: =VLOOKUP(Tabela2[[#This Row],[Funcionários]],'CADASTRO DE FUNCIONÁRIOS'!A:F,4,0) -> 4000 | F8: 240 | G8: 480 | H8: 280 | I8: 142 | J8: =Tabela2[[#This Row],[Quantidade HE]]*VLOOKUP(Tabela2[[#This Row],[Funcionários]],'CADASTRO DE FUNCIONÁRIOS'!A:F,6,0) -> 81.818182 | K8: =Tabela2[[#This Row],[Salário bruto]]-(SUM(Tabela2[[#This Row],[Desconto transporte]:[Outros descontos]]))+Tabela2[[#This Row],[Valor da hora extra]] -> 2939.8182
A9: Luana Silva | B9: 45292 | C9: 45323 | D9: 2 | E9: =VLOOKUP(Tabela2[[#This Row],[Funcionários]],'CADASTRO DE FUNCIONÁRIOS'!A:F,4,0) -> 3000 | F9: 180 | G9: 300 | H9: 210 | I9: 144 | J9: =Tabela2[[#This Row],[Quantidade HE]]*VLOOKUP(Tabela2[[#This Row],[Funcionários]],'CADASTRO DE FUNCIONÁRIOS'!A:F,6,0) -> 40.909091 | K9: =Tabela2[[#This Row],[Salário bruto]]-(SUM(Tabela2[[#This Row],[Desconto transporte]:[Outros descontos]]))+Tabela2[[#This Row],[Valor da hora extra]] -> 2206.9091
A10: Thiago Gonçalves | B10: 45292 | C10: 45323 | D10: 6 | E10: =VLOOKUP(Tabela2[[#This Row],[Funcionários]],'CADASTRO DE FUNCIONÁRIOS'!A:F,4,0) -> 2000 | F10: 120 | G10: 220 | H10: 200 | I10: 108 | J10: =Tabela2[[#This Row],[Quantidade HE]]*VLOOKUP(Tabela2[[#This Row],[Funcionários]],'CADASTRO DE FUNCIONÁRIOS'!A:F,6,0) -> 0 | K10: =Tabela2[[#This Row],[Salário bruto]]-(SUM(Tabela2[[#This Row],[Desconto transporte]:[Outros descontos]]))+Tabela2[[#This Row],[Valor da hora extra]] -> 1352
A11: Lucas da Rocha | B11: 45292 | C11: 45323 | D11: 7 | E11: =VLOOKUP(Tabela2[[#This Row],[Funcionários]],'CADASTRO DE FUNCIONÁRIOS'!A:F,4,0) -> 1000 | F11: 70 | G11: 120 | H11: 90 | I11: 135 | J11: =Tabela2[[#This Row],[Quantidade HE]]*VLOOKUP(Tabela2[[#This Row],[Funcionários]],'CADASTRO DE FUNCIONÁRIOS'!A:F,6,0) -> 0 | K11: =Tabela2[[#This Row],[Salário bruto]]-(SUM(Tabela2[[#This Row],[Desconto transporte]:[Outros descontos]]))+Tabela2[[#This Row],[Valor da hora extra]] -> 585
A12: Maria Julia Ribeiro | B12: 45292 | C12: 45323 | D12: 3 | E12: =VLOOKUP(Tabela2[[#This Row],[Funcionários]],'CADASTRO DE FUNCIONÁRIOS'!A:F,4,0) -> 2400 | F12: 100 | G12: 220 | H12: 200 | I12: 113 | J12: =Tabela2[[#This Row],[Quantidade HE]]*VLOOKUP(Tabela2[[#This Row],[Funcionários]],'CADASTRO DE FUNCIONÁRIOS'!A:F,6,0) -> 49.090909 | K12: =Tabela2[[#This Row],[Salário bruto]]-(SUM(Tabela2[[#This Row],[Desconto transporte]:[Outros descontos]]))+Tabela2[[#This Row],[Valor da hora extra]] -> 1816.0909
A13: Liliam da Silva Prado | B13: 45292 | C13: 45323 | D13: 6 | E13: =VLOOKUP(Tabela2[[#This Row],[Funcionários]],'CADASTRO DE FUNCIONÁRIOS'!A:F,4,0) -> 1800 | F13: 150 | G13: 160 | H13: 215 | I13: 134 | J13: =Tabela2[[#This Row],[Quantidade HE]]*VLOOKUP(Tabela2[[#This Row],[Funcionários]],'CADASTRO DE FUNCIONÁRIOS'!A:F,6,0) -> 73.636364 | K13: =Tabela2[[#This Row],[Salário bruto]]-(SUM(Tabela2[[#This Row],[Desconto transporte]:[Outros descontos]]))+Tabela2[[#This Row],[Valor da hora extra]] -> 1214.6364
A14: Katarina Damasceno | B14: 45323 | C14: 45352 | D14: 4 | E14: =VLOOKUP(Tabela2[[#This Row],[Funcionários]],'CADASTRO DE FUNCIONÁRIOS'!A:F,4,0) -> 20000 | F14: 1000 | G14: 2400 | H14: 1800 | I14: 154 | J14: =Tabela2[[#This Row],[Quantidade HE]]*VLOOKUP(Tabela2[[#This Row],[Funcionários]],'CADASTRO DE FUNCIONÁRIOS'!A:F,6,0) -> 0 | K14: =Tabela2[[#This Row],[Salário bruto]]-(SUM(Tabela2[[#This Row],[Desconto transporte]:[Outros descontos]]))+Tabela2[[#This Row],[Valor da hora extra]] -> 14646
A15: Jorge Henrique Martins | B15: 45323 | C15: 45352 | D15: 2 | E15: =VLOOKUP(Tabela2[[#This Row],[Funcionários]],'CADASTRO DE FUNCIONÁRIOS'!A:F,4,0) -> 8000 | F15: 560 | G15: 960 | H15: 640 | I15: 126 | J15: =Tabela2[[#This Row],[Quantidade HE]]*VLOOKUP(Tabela2[[#This Row],[Funcionários]],'CADASTRO DE FUNCIONÁRIOS'!A:F,6,0) -> 109.09091 | K15: =Tabela2[[#This Row],[Salário bruto]]-(SUM(Tabela2[[#This Row],[Desconto transporte]:[Outros descontos]]))+Tabela2[[#This Row],[Valor da hora extra]] -> 5823.0909
A16: Mariana Dias | B16: 45323 | C16: 45352 | D16: 7 | E16: =VLOOKUP(Tabela2[[#This Row],[Funcionários]],'CADASTRO DE FUNCIONÁRIOS'!A:F,4,0) -> 6500 | F16: 390 | G16: 715 | H16: 650 | I16: 149 | J16: =Tabela2[[#This Row],[Quantidade HE]]*VLOOKUP(Tabela2[[#This Row],[Funcionários]],'CADASTRO DE FUNCIONÁRIOS'!A:F,6,0) -> 310.22727 | K16: =Tabela2[[#This Row],[Salário bruto]]-(SUM(Tabela2[[#This Row],[Desconto transporte]:[Outros descontos]]))+Tabela2[[#This Row],[Valor da hora extra]] -> 4906.2273
... A112: Liliam da Silva Prado | B112: 45627 | C112: 45658 | D112: 5 | E112: =VLOOKUP(Tabela2[[#This Row],[Funcionários]],'CADASTRO DE FUNCIONÁRIOS'!A:F,4,0) -> 1800 | F112: 150 | G112: 160 | H112: 215 | I112: 131 | J112: =Tabela2[[#This Row],[Quantidade HE]]*VLOOKUP(Tabela2[[#This Row],[Funcionários]],'CADASTRO DE FUNCIONÁRIOS'!A:F,6,0) -> 61.363636 | K112: =Tabela2[[#This Row],[Salário bruto]]-(SUM(Tabela2[[#This Row],[Desconto transporte]:[Outros descontos]]))+Tabela2[[#This Row],[Valor da hora extra]] -> 1205.3636

Sheet DASHBOARD

Sheet GRÁFICOS
A3: Meses | B3: Soma de Salário líquido
A4: jan | B4: 35377.091
A5: fev | B5: 35454.818
A6: mar | B6: 35399.591
A7: abr | B7: 35560.545
A8: mai | B8: 35532.818
A9: jun | B9: 35569.909
A10: jul | B10: 35917.591
A11: ago | B11: 35745.591
A12: set | B12: 35639.545
A13: out | B13: 35410.955
A14: nov | B14: 35122.909
A15: dez | B15: 35569.273
A16: Total Geral | B16: 426300.64
A19: Funcionários | B19: Soma de Salário líquido
A20: Jorge Henrique Martins | B20: 71273.273
A21: Katarina Damasceno | B21: 175934
A22: Leonargo Rangel | B22: 35756.091
A23: Liliam da Silva Prado | B23: 14193.727
A24: Luana Silva | B24: 27105.909
A25: Lucas da Rocha | B25: 7079
A26: Maria Julia Ribeiro | B26: 21920.909
A27: Mariana Dias | B27: 57107.727
A28: Thiago Gonçalves | B28: 15930
A29: Total Geral | B29: 426300.64
A32: Funcionários | B32: Soma de Quantidade HE
A33: Jorge Henrique Martins | B33: 50
A34: Katarina Damasceno | B34: 44
A35: Leonargo Rangel | B35: 48
A36: Liliam da Silva Prado | B36: 43
A37: Luana Silva | B37: 46
A38: Lucas da Rocha | B38: 42
A39: Maria Julia Ribeiro | B39: 52
A40: Mariana Dias | B40: 40
A41: Thiago Gonçalves | B41: 44
A42: Total Geral | B42: 409
A45: Meses | B45: Soma de Desconto INSS
A46: jan | B46: 4285
A47: fev | B47: 4285
A48: mar | B48: 4285
...
